<robot name="husky">

    <link name="dual_arm_bulkhead_link">
        <visual>
            <origin rpy="0 0 0" xyz="0 0 0" />
            <geometry>
                <mesh filename="package://husky_ur_description/meshes/dual_arm_bulkhead.obj" />
            </geometry>
        </visual>
        <collision>
            <origin rpy="0 0 0" xyz="0 0 0" />
            <geometry>
                <mesh filename="package://husky_ur_description/meshes/dual_arm_bulkhead_collision.obj" />
            </geometry>
        </collision>
        
<inertial>
            <mass value="0.1" />
            <inertia ixx="0.03" iyy="0.03" izz="0.03" ixy="0.0" ixz="0.0" iyz="0.0" />
        </inertial>

    </link>
    <joint name="dual_arm_bulkhead_joint" type="fixed">
        <parent link="base_link" />
        <child link="dual_arm_bulkhead_link" />
        <origin rpy="0 0 0" xyz="0 0 0.224" />
    </joint>


    <link name="left_arm_bulkhead_link" />
    <joint name="left_arm_bulkhead_joint" type="fixed">
        <parent link="dual_arm_bulkhead_link" />
        <child link="left_arm_bulkhead_link" />
        <origin rpy="0 -0.785398163397 -1.57079632679" xyz="0.1225 0.14891 0.13371" />
    </joint>
    <link name="right_arm_bulkhead_link" />
    <joint name="right_arm_bulkhead_joint" type="fixed">
        <parent link="dual_arm_bulkhead_link" />
        <child link="right_arm_bulkhead_link" />
        <origin rpy="0 0.785398163397 -1.57079632679" xyz="0.1225 -0.14891 0.13371" />
    </joint>
    <joint name="dual_arm_bulkhead_joint" type="fixed">
        <parent link="base_link" />
        <child link="dual_arm_bulkhead_link" />
        <origin rpy="0 0 0" xyz="0 0 0.224" />
    </joint>
    <joint name="left_arm_mount_joint" type="fixed">
        <parent link="left_arm_bulkhead_link" />
        <child link="left_ur_arm_base_link" />
        <origin rpy="0 0 0" xyz="0 0 0" />
    </joint>
    <joint name="right_arm_mount_joint" type="fixed">
        <parent link="right_arm_bulkhead_link" />
        <child link="right_ur_arm_base_link" />
        <origin rpy="0 0 0" xyz="0 0 0" />
    </joint>

    <!--
    Base UR robot series xacro macro.

    NOTE: this is NOT a URDF. It cannot directly be loaded by consumers
    expecting a flattened '.urdf' file. See the top-level '.xacro' for that
    (but note: that .xacro must still be processed by the xacro command).

    For use in '.launch' files: use one of the 'load_urX.launch' convenience
    launch files.

    This file models the base kinematic chain of a UR robot, which then gets
    parameterised by various configuration files to convert it into a UR3(e),
    UR5(e), UR10(e) or UR16e.

    NOTE: the default kinematic parameters (ie: link lengths, frame locations,
    offets, etc) do not correspond to any particular robot. They are defaults
    only. There WILL be non-zero offsets between the Forward Kinematics results
    in TF (ie: robot_state_publisher) and the values reported by the Teach
    Pendant.

    For accurate (and robot-specific) transforms, the 'kinematics_parameters_file'
    parameter MUST point to a .yaml file containing the appropriate values for
    the targetted robot.

    If using the UniversalRobots/Universal_Robots_ROS_Driver, follow the steps
    described in the readme of that repository to extract the kinematic
    calibration from the controller and generate the required .yaml file.

    Main author of the migration to yaml configs: Ludovic Delval.

    Contributors to previous versions (in no particular order):

     - Felix Messmer
     - Kelsey Hawkins
     - Wim Meeussen
     - Shaun Edwards
     - Nadia Hammoudeh Garcia
     - Dave Hershberger
     - G. vd. Hoorn
     - Philip Long
     - Dave Coleman
     - Miguel Prada
     - Mathias Luedtke
     - Marcel Schnirring
     - Felix von Drigalski
     - Felix Exner
     - Jimmy Da Silva
     - Ajit Krisshna N L
     - Muhammad Asif Rana
  -->
    <!--
    NOTE: the macro defined in this file is NOT part of the public API of this
          package. Users CANNOT rely on this file being available, or stored in
          this location. Nor can they rely on the existence of the macro.
  -->
    <transmission name="right_ur_arm_shoulder_pan_trans">
        <type>transmission_interface/SimpleTransmission</type>
        <joint name="right_ur_arm_shoulder_pan_joint">
            <hardwareInterface>hardware_interface/PositionJointInterface</hardwareInterface>
        </joint>
        <actuator name="right_ur_arm_shoulder_pan_motor">
            <mechanicalReduction>1</mechanicalReduction>
        </actuator>
    </transmission>
    <transmission name="right_ur_arm_shoulder_lift_trans">
        <type>transmission_interface/SimpleTransmission</type>
        <joint name="right_ur_arm_shoulder_lift_joint">
            <hardwareInterface>hardware_interface/PositionJointInterface</hardwareInterface>
        </joint>
        <actuator name="right_ur_arm_shoulder_lift_motor">
            <mechanicalReduction>1</mechanicalReduction>
        </actuator>
    </transmission>
    <transmission name="right_ur_arm_elbow_trans">
        <type>transmission_interface/SimpleTransmission</type>
        <joint name="right_ur_arm_elbow_joint">
            <hardwareInterface>hardware_interface/PositionJointInterface</hardwareInterface>
        </joint>
        <actuator name="right_ur_arm_elbow_motor">
            <mechanicalReduction>1</mechanicalReduction>
        </actuator>
    </transmission>
    <transmission name="right_ur_arm_wrist_1_trans">
        <type>transmission_interface/SimpleTransmission</type>
        <joint name="right_ur_arm_wrist_1_joint">
            <hardwareInterface>hardware_interface/PositionJointInterface</hardwareInterface>
        </joint>
        <actuator name="right_ur_arm_wrist_1_motor">
            <mechanicalReduction>1</mechanicalReduction>
        </actuator>
    </transmission>
    <transmission name="right_ur_arm_wrist_2_trans">
        <type>transmission_interface/SimpleTransmission</type>
        <joint name="right_ur_arm_wrist_2_joint">
            <hardwareInterface>hardware_interface/PositionJointInterface</hardwareInterface>
        </joint>
        <actuator name="right_ur_arm_wrist_2_motor">
            <mechanicalReduction>1</mechanicalReduction>
        </actuator>
    </transmission>
    <transmission name="right_ur_arm_wrist_3_trans">
        <type>transmission_interface/SimpleTransmission</type>
        <joint name="right_ur_arm_wrist_3_joint">
            <hardwareInterface>hardware_interface/PositionJointInterface</hardwareInterface>
        </joint>
        <actuator name="right_ur_arm_wrist_3_motor">
            <mechanicalReduction>1</mechanicalReduction>
        </actuator>
    </transmission>
    <!-- links: main serial chain -->
    <link name="right_ur_arm_base_link" />
    <link name="right_ur_arm_base_link_inertia">
        <visual>
            <origin rpy="0 0 3.14159265359" xyz="0 0 0" />
            <geometry>
                <mesh filename="package://ur_description/meshes/ur5e/visual/base.obj" />
            </geometry>
            <material name="LightGrey">
                <color rgba="0.7 0.7 0.7 1.0" />
            </material>
        </visual>
        <collision>
            <origin rpy="0 0 3.14159265359" xyz="0 0 0" />
            <geometry>
                <mesh filename="package://ur_description/meshes/ur5e/collision/base.stl" />
            </geometry>
        </collision>
        
<inertial>
            <mass value="4.0" />
            <origin rpy="0 0 0" xyz="0 0 0" />
            <inertia ixx="0.00443333156" ixy="0.0" ixz="0.0" iyy="0.00443333156" iyz="0.0" izz="0.0072" />
        </inertial>

    </link>
    <link name="right_ur_arm_shoulder_link">
        <visual>
            <origin rpy="0 0 3.14159265359" xyz="0 0 0" />
            <geometry>
                <mesh filename="package://ur_description/meshes/ur5e/visual/shoulder.obj" />
            </geometry>
            <material name="LightGrey">
                <color rgba="0.7 0.7 0.7 1.0" />
            </material>
        </visual>
        <collision>
            <origin rpy="0 0 3.14159265359" xyz="0 0 0" />
            <geometry>
                <mesh filename="package://ur_description/meshes/ur5e/collision/shoulder.stl" />
            </geometry>
        </collision>
        
<inertial>
            <mass value="3.7" />
            <origin rpy="0 0 0" xyz="0 0 0" />
            <inertia ixx="0.010267495893" ixy="0.0" ixz="0.0" iyy="0.010267495893" iyz="0.0" izz="0.00666" />
        </inertial>

    </link>
    <link name="right_ur_arm_upper_arm_link">
        <visual>
            <origin rpy="1.57079632679 0 -1.57079632679" xyz="0 0 0.138" />
            <geometry>
                <mesh filename="package://ur_description/meshes/ur5e/visual/upperarm.obj" />
            </geometry>
            <material name="LightGrey">
                <color rgba="0.7 0.7 0.7 1.0" />
            </material>
        </visual>
        <collision>
            <origin rpy="1.57079632679 0 -1.57079632679" xyz="0 0 0.138" />
            <geometry>
                <mesh filename="package://ur_description/meshes/ur5e/collision/upperarm.stl" />
            </geometry>
        </collision>
        
<inertial>
            <mass value="8.393" />
            <origin rpy="0 1.57079632679 0" xyz="-0.2125 0.0 0.138" />
            <inertia ixx="0.133885781862" ixy="0.0" ixz="0.0" iyy="0.133885781862" iyz="0.0" izz="0.0151074" />
        </inertial>

    </link>
    <link name="right_ur_arm_forearm_link">
        <visual>
            <origin rpy="1.57079632679 0 -1.57079632679" xyz="0 0 0.007" />
            <geometry>
                <mesh filename="package://ur_description/meshes/ur5e/visual/forearm.obj" />
            </geometry>
            <material name="LightGrey">
                <color rgba="0.7 0.7 0.7 1.0" />
            </material>
        </visual>
        <collision>
            <origin rpy="1.57079632679 0 -1.57079632679" xyz="0 0 0.007" />
            <geometry>
                <mesh filename="package://ur_description/meshes/ur5e/collision/forearm.stl" />
            </geometry>
        </collision>
        
<inertial>
            <mass value="2.275" />
            <origin rpy="0 1.57079632679 0" xyz="-0.1961 0.0 0.007" />
            <inertia ixx="0.0312093550996" ixy="0.0" ixz="0.0" iyy="0.0312093550996" iyz="0.0" izz="0.004095" />
        </inertial>

    </link>
    <link name="right_ur_arm_wrist_1_link">
        <visual>
            <!-- TODO: Move this to a parameter -->
            <origin rpy="1.57079632679 0 0" xyz="0 0 -0.127" />
            <geometry>
                <mesh filename="package://ur_description/meshes/ur5e/visual/wrist1.obj" />
            </geometry>
            <material name="LightGrey">
                <color rgba="0.7 0.7 0.7 1.0" />
            </material>
        </visual>
        <collision>
            <origin rpy="1.57079632679 0 0" xyz="0 0 -0.127" />
            <geometry>
                <mesh filename="package://ur_description/meshes/ur5e/collision/wrist1.stl" />
            </geometry>
        </collision>
        
<inertial>
            <mass value="1.219" />
            <origin rpy="0 0 0" xyz="0 0 0" />
            <inertia ixx="0.00255989897604" ixy="0.0" ixz="0.0" iyy="0.00255989897604" iyz="0.0" izz="0.0021942" />
        </inertial>

    </link>
    <link name="right_ur_arm_wrist_2_link">
        <visual>
            <origin rpy="0 0 0" xyz="0 0 -0.0997" />
            <geometry>
                <mesh filename="package://ur_description/meshes/ur5e/visual/wrist2.obj" />
            </geometry>
            <material name="LightGrey">
                <color rgba="0.7 0.7 0.7 1.0" />
            </material>
        </visual>
        <collision>
            <origin rpy="0 0 0" xyz="0 0 -0.0997" />
            <geometry>
                <mesh filename="package://ur_description/meshes/ur5e/collision/wrist2.stl" />
            </geometry>
        </collision>
        
<inertial>
            <mass value="1.219" />
            <origin rpy="0 0 0" xyz="0 0 0" />
            <inertia ixx="0.00255989897604" ixy="0.0" ixz="0.0" iyy="0.00255989897604" iyz="0.0" izz="0.0021942" />
        </inertial>

    </link>
    <link name="right_ur_arm_wrist_3_link">
        <visual>
            <origin rpy="1.57079632679 0 0" xyz="0 0 -0.0989" />
            <geometry>
                <mesh filename="package://ur_description/meshes/ur5e/visual/wrist3.obj" />
            </geometry>
            <material name="LightGrey">
                <color rgba="0.7 0.7 0.7 1.0" />
            </material>
        </visual>
        <collision>
            <origin rpy="1.57079632679 0 0" xyz="0 0 -0.0989" />
            <geometry>
                <mesh filename="package://ur_description/meshes/ur5e/collision/wrist3.stl" />
            </geometry>
        </collision>
        
<inertial>
            <mass value="0.1879" />
            <origin rpy="0 0 0" xyz="0.0 0.0 -0.0229" />
            <inertia ixx="9.89041005217e-05" ixy="0.0" ixz="0.0" iyy="9.89041005217e-05" iyz="0.0" izz="0.0001321171875" />
        </inertial>

    </link>
    <!-- joints: main serial chain -->
    <joint name="right_ur_arm_base_link-base_link_inertia" type="fixed">
        <parent link="right_ur_arm_base_link" />
        <child link="right_ur_arm_base_link_inertia" />
        <!-- 'base_link' is REP-103 aligned (so X+ forward), while the internal
           frames of the robot/controller have X+ pointing backwards.
           Use the joint between 'base_link' and 'base_link_inertia' (a dummy
           link/frame) to introduce the necessary rotation over Z (of pi rad).
      -->
        <origin rpy="0 0 3.14159265359" xyz="0 0 0" />
    </joint>
    <joint name="right_ur_arm_shoulder_pan_joint" type="revolute">
        <parent link="right_ur_arm_base_link_inertia" />
        <child link="right_ur_arm_shoulder_link" />
        <origin rpy="0 0 0" xyz="0 0 0.1625" />
        <axis xyz="0 0 1" />
        <limit effort="150.0" lower="-6.28318530718" upper="6.28318530718" velocity="3.14159265359" />
        <dynamics damping="0" friction="0" />
    </joint>
    <joint name="right_ur_arm_shoulder_lift_joint" type="revolute">
        <parent link="right_ur_arm_shoulder_link" />
        <child link="right_ur_arm_upper_arm_link" />
        <origin rpy="1.570796327 0 0" xyz="0 0 0" />
        <axis xyz="0 0 1" />
        <limit effort="150.0" lower="-6.28318530718" upper="6.28318530718" velocity="3.14159265359" />
        <dynamics damping="0" friction="0" />
    </joint>
    <joint name="right_ur_arm_elbow_joint" type="revolute">
        <parent link="right_ur_arm_upper_arm_link" />
        <child link="right_ur_arm_forearm_link" />
        <origin rpy="0 0 0" xyz="-0.425 0 0" />
        <axis xyz="0 0 1" />
        <limit effort="150.0" lower="-3.14159265359" upper="3.14159265359" velocity="3.14159265359" />
        <dynamics damping="0" friction="0" />
    </joint>
    <joint name="right_ur_arm_wrist_1_joint" type="revolute">
        <parent link="right_ur_arm_forearm_link" />
        <child link="right_ur_arm_wrist_1_link" />
        <origin rpy="0 0 0" xyz="-0.3922 0 0.1333" />
        <axis xyz="0 0 1" />
        <limit effort="28.0" lower="-6.28318530718" upper="6.28318530718" velocity="3.14159265359" />
        <dynamics damping="0" friction="0" />
    </joint>
    <joint name="right_ur_arm_wrist_2_joint" type="revolute">
        <parent link="right_ur_arm_wrist_1_link" />
        <child link="right_ur_arm_wrist_2_link" />
        <origin rpy="1.570796327 0 0" xyz="0 -0.0997 -2.0448811823e-11" />
        <axis xyz="0 0 1" />
        <limit effort="28.0" lower="-6.28318530718" upper="6.28318530718" velocity="3.14159265359" />
        <dynamics damping="0" friction="0" />
    </joint>
    <joint name="right_ur_arm_wrist_3_joint" type="revolute">
        <parent link="right_ur_arm_wrist_2_link" />
        <child link="right_ur_arm_wrist_3_link" />
        <origin rpy="1.57079632659 3.14159265359 3.14159265359" xyz="0 0.0996 -2.04283014801e-11" />
        <axis xyz="0 0 1" />
        <limit effort="28.0" lower="-6.28318530718" upper="6.28318530718" velocity="3.14159265359" />
        <dynamics damping="0" friction="0" />
    </joint>
    <!-- ROS-Industrial 'base' frame: base_link to UR 'Base' Coordinates transform -->
    <link name="right_ur_arm_base" />
    <joint name="right_ur_arm_base_link-base_fixed_joint" type="fixed">
        <!-- Note the rotation over Z of pi radians: as base_link is REP-103
           aligned (ie: has X+ forward, Y+ left and Z+ up), this is needed
           to correctly align 'base' with the 'Base' coordinate system of
           the UR controller.
      -->
        <origin rpy="0 0 3.14159265359" xyz="0 0 0" />
        <parent link="right_ur_arm_base_link" />
        <child link="right_ur_arm_base" />
    </joint>
    <!-- ROS-Industrial 'flange' frame: attachment point for EEF models -->
    <link name="right_ur_arm_flange" />
    <joint name="right_ur_arm_wrist_3-flange" type="fixed">
        <parent link="right_ur_arm_wrist_3_link" />
        <child link="right_ur_arm_flange" />
        <origin rpy="0 -1.57079632679 -1.57079632679" xyz="0 0 0" />
    </joint>
    <!-- ROS-Industrial 'tool0' frame: all-zeros tool frame -->
    <link name="right_ur_arm_tool0" />
    <joint name="right_ur_arm_flange-tool0" type="fixed">
        <!-- default toolframe: X+ left, Y+ up, Z+ front -->
        <origin rpy="1.57079632679 0 1.57079632679" xyz="0 0 0" />
        <parent link="right_ur_arm_flange" />
        <child link="right_ur_arm_tool0" />
    </joint>
    <!--
    Base UR robot series xacro macro.

    NOTE: this is NOT a URDF. It cannot directly be loaded by consumers
    expecting a flattened '.urdf' file. See the top-level '.xacro' for that
    (but note: that .xacro must still be processed by the xacro command).

    For use in '.launch' files: use one of the 'load_urX.launch' convenience
    launch files.

    This file models the base kinematic chain of a UR robot, which then gets
    parameterised by various configuration files to convert it into a UR3(e),
    UR5(e), UR10(e) or UR16e.

    NOTE: the default kinematic parameters (ie: link lengths, frame locations,
    offets, etc) do not correspond to any particular robot. They are defaults
    only. There WILL be non-zero offsets between the Forward Kinematics results
    in TF (ie: robot_state_publisher) and the values reported by the Teach
    Pendant.

    For accurate (and robot-specific) transforms, the 'kinematics_parameters_file'
    parameter MUST point to a .yaml file containing the appropriate values for
    the targetted robot.

    If using the UniversalRobots/Universal_Robots_ROS_Driver, follow the steps
    described in the readme of that repository to extract the kinematic
    calibration from the controller and generate the required .yaml file.

    Main author of the migration to yaml configs: Ludovic Delval.

    Contributors to previous versions (in no particular order):

     - Felix Messmer
     - Kelsey Hawkins
     - Wim Meeussen
     - Shaun Edwards
     - Nadia Hammoudeh Garcia
     - Dave Hershberger
     - G. vd. Hoorn
     - Philip Long
     - Dave Coleman
     - Miguel Prada
     - Mathias Luedtke
     - Marcel Schnirring
     - Felix von Drigalski
     - Felix Exner
     - Jimmy Da Silva
     - Ajit Krisshna N L
     - Muhammad Asif Rana
  -->
    <!--
    NOTE: the macro defined in this file is NOT part of the public API of this
          package. Users CANNOT rely on this file being available, or stored in
          this location. Nor can they rely on the existence of the macro.
  -->
    <transmission name="left_ur_arm_shoulder_pan_trans">
        <type>transmission_interface/SimpleTransmission</type>
        <joint name="left_ur_arm_shoulder_pan_joint">
            <hardwareInterface>hardware_interface/PositionJointInterface</hardwareInterface>
        </joint>
        <actuator name="left_ur_arm_shoulder_pan_motor">
            <mechanicalReduction>1</mechanicalReduction>
        </actuator>
    </transmission>
    <transmission name="left_ur_arm_shoulder_lift_trans">
        <type>transmission_interface/SimpleTransmission</type>
        <joint name="left_ur_arm_shoulder_lift_joint">
            <hardwareInterface>hardware_interface/PositionJointInterface</hardwareInterface>
        </joint>
        <actuator name="left_ur_arm_shoulder_lift_motor">
            <mechanicalReduction>1</mechanicalReduction>
        </actuator>
    </transmission>
    <transmission name="left_ur_arm_elbow_trans">
        <type>transmission_interface/SimpleTransmission</type>
        <joint name="left_ur_arm_elbow_joint">
            <hardwareInterface>hardware_interface/PositionJointInterface</hardwareInterface>
        </joint>
        <actuator name="left_ur_arm_elbow_motor">
            <mechanicalReduction>1</mechanicalReduction>
        </actuator>
    </transmission>
    <transmission name="left_ur_arm_wrist_1_trans">
        <type>transmission_interface/SimpleTransmission</type>
        <joint name="left_ur_arm_wrist_1_joint">
            <hardwareInterface>hardware_interface/PositionJointInterface</hardwareInterface>
        </joint>
        <actuator name="left_ur_arm_wrist_1_motor">
            <mechanicalReduction>1</mechanicalReduction>
        </actuator>
    </transmission>
    <transmission name="left_ur_arm_wrist_2_trans">
        <type>transmission_interface/SimpleTransmission</type>
        <joint name="left_ur_arm_wrist_2_joint">
            <hardwareInterface>hardware_interface/PositionJointInterface</hardwareInterface>
        </joint>
        <actuator name="left_ur_arm_wrist_2_motor">
            <mechanicalReduction>1</mechanicalReduction>
        </actuator>
    </transmission>
    <transmission name="left_ur_arm_wrist_3_trans">
        <type>transmission_interface/SimpleTransmission</type>
        <joint name="left_ur_arm_wrist_3_joint">
            <hardwareInterface>hardware_interface/PositionJointInterface</hardwareInterface>
        </joint>
        <actuator name="left_ur_arm_wrist_3_motor">
            <mechanicalReduction>1</mechanicalReduction>
        </actuator>
    </transmission>
    <!-- links: main serial chain -->
    <link name="left_ur_arm_base_link" />
    <link name="left_ur_arm_base_link_inertia">
        <visual>
            <origin rpy="0 0 3.14159265359" xyz="0 0 0" />
            <geometry>
                <mesh filename="package://ur_description/meshes/ur5e/visual/base.obj" />
            </geometry>
            <material name="LightGrey">
                <color rgba="0.7 0.7 0.7 1.0" />
            </material>
        </visual>
        <collision>
            <origin rpy="0 0 3.14159265359" xyz="0 0 0" />
            <geometry>
                <mesh filename="package://ur_description/meshes/ur5e/collision/base.stl" />
            </geometry>
        </collision>
        
<inertial>
            <mass value="4.0" />
            <origin rpy="0 0 0" xyz="0 0 0" />
            <inertia ixx="0.00443333156" ixy="0.0" ixz="0.0" iyy="0.00443333156" iyz="0.0" izz="0.0072" />
        </inertial>

    </link>
    <link name="left_ur_arm_shoulder_link">
        <visual>
            <origin rpy="0 0 3.14159265359" xyz="0 0 0" />
            <geometry>
                <mesh filename="package://ur_description/meshes/ur5e/visual/shoulder.obj" />
            </geometry>
            <material name="LightGrey">
                <color rgba="0.7 0.7 0.7 1.0" />
            </material>
        </visual>
        <collision>
            <origin rpy="0 0 3.14159265359" xyz="0 0 0" />
            <geometry>
                <mesh filename="package://ur_description/meshes/ur5e/collision/shoulder.stl" />
            </geometry>
        </collision>
        
<inertial>
            <mass value="3.7" />
            <origin rpy="0 0 0" xyz="0 0 0" />
            <inertia ixx="0.010267495893" ixy="0.0" ixz="0.0" iyy="0.010267495893" iyz="0.0" izz="0.00666" />
        </inertial>

    </link>
    <link name="left_ur_arm_upper_arm_link">
        <visual>
            <origin rpy="1.57079632679 0 -1.57079632679" xyz="0 0 0.138" />
            <geometry>
                <mesh filename="package://ur_description/meshes/ur5e/visual/upperarm.obj" />
            </geometry>
            <material name="LightGrey">
                <color rgba="0.7 0.7 0.7 1.0" />
            </material>
        </visual>
        <collision>
            <origin rpy="1.57079632679 0 -1.57079632679" xyz="0 0 0.138" />
            <geometry>
                <mesh filename="package://ur_description/meshes/ur5e/collision/upperarm.stl" />
            </geometry>
        </collision>
        
<inertial>
            <mass value="8.393" />
            <origin rpy="0 1.57079632679 0" xyz="-0.2125 0.0 0.138" />
            <inertia ixx="0.133885781862" ixy="0.0" ixz="0.0" iyy="0.133885781862" iyz="0.0" izz="0.0151074" />
        </inertial>

    </link>
    <link name="left_ur_arm_forearm_link">
        <visual>
            <origin rpy="1.57079632679 0 -1.57079632679" xyz="0 0 0.007" />
            <geometry>
                <mesh filename="package://ur_description/meshes/ur5e/visual/forearm.obj" />
            </geometry>
            <material name="LightGrey">
                <color rgba="0.7 0.7 0.7 1.0" />
            </material>
        </visual>
        <collision>
            <origin rpy="1.57079632679 0 -1.57079632679" xyz="0 0 0.007" />
            <geometry>
                <mesh filename="package://ur_description/meshes/ur5e/collision/forearm.stl" />
            </geometry>
        </collision>
        
<inertial>
            <mass value="2.275" />
            <origin rpy="0 1.57079632679 0" xyz="-0.1961 0.0 0.007" />
            <inertia ixx="0.0312093550996" ixy="0.0" ixz="0.0" iyy="0.0312093550996" iyz="0.0" izz="0.004095" />
        </inertial>

    </link>
    <link name="left_ur_arm_wrist_1_link">
        <visual>
            <!-- TODO: Move this to a parameter -->
            <origin rpy="1.57079632679 0 0" xyz="0 0 -0.127" />
            <geometry>
                <mesh filename="package://ur_description/meshes/ur5e/visual/wrist1.obj" />
            </geometry>
            <material name="LightGrey">
                <color rgba="0.7 0.7 0.7 1.0" />
            </material>
        </visual>
        <collision>
            <origin rpy="1.57079632679 0 0" xyz="0 0 -0.127" />
            <geometry>
                <mesh filename="package://ur_description/meshes/ur5e/collision/wrist1.stl" />
            </geometry>
        </collision>
        
<inertial>
            <mass value="1.219" />
            <origin rpy="0 0 0" xyz="0 0 0" />
            <inertia ixx="0.00255989897604" ixy="0.0" ixz="0.0" iyy="0.00255989897604" iyz="0.0" izz="0.0021942" />
        </inertial>

    </link>
    <link name="left_ur_arm_wrist_2_link">
        <visual>
            <origin rpy="0 0 0" xyz="0 0 -0.0997" />
            <geometry>
                <mesh filename="package://ur_description/meshes/ur5e/visual/wrist2.obj" />
            </geometry>
            <material name="LightGrey">
                <color rgba="0.7 0.7 0.7 1.0" />
            </material>
        </visual>
        <collision>
            <origin rpy="0 0 0" xyz="0 0 -0.0997" />
            <geometry>
                <mesh filename="package://ur_description/meshes/ur5e/collision/wrist2.stl" />
            </geometry>
        </collision>
        
<inertial>
            <mass value="1.219" />
            <origin rpy="0 0 0" xyz="0 0 0" />
            <inertia ixx="0.00255989897604" ixy="0.0" ixz="0.0" iyy="0.00255989897604" iyz="0.0" izz="0.0021942" />
        </inertial>

    </link>
    <link name="left_ur_arm_wrist_3_link">
        <visual>
            <origin rpy="1.57079632679 0 0" xyz="0 0 -0.0989" />
            <geometry>
                <mesh filename="package://ur_description/meshes/ur5e/visual/wrist3.obj" />
            </geometry>
            <material name="LightGrey">
                <color rgba="0.7 0.7 0.7 1.0" />
            </material>
        </visual>
        <collision>
            <origin rpy="1.57079632679 0 0" xyz="0 0 -0.0989" />
            <geometry>
                <mesh filename="package://ur_description/meshes/ur5e/collision/wrist3.stl" />
            </geometry>
        </collision>
        
<inertial>
            <mass value="0.1879" />
            <origin rpy="0 0 0" xyz="0.0 0.0 -0.0229" />
            <inertia ixx="9.89041005217e-05" ixy="0.0" ixz="0.0" iyy="9.89041005217e-05" iyz="0.0" izz="0.0001321171875" />
        </inertial>

    </link>
    <!-- joints: main serial chain -->
    <joint name="left_ur_arm_base_link-base_link_inertia" type="fixed">
        <parent link="left_ur_arm_base_link" />
        <child link="left_ur_arm_base_link_inertia" />
        <!-- 'base_link' is REP-103 aligned (so X+ forward), while the internal
           frames of the robot/controller have X+ pointing backwards.
           Use the joint between 'base_link' and 'base_link_inertia' (a dummy
           link/frame) to introduce the necessary rotation over Z (of pi rad).
      -->
        <origin rpy="0 0 3.14159265359" xyz="0 0 0" />
    </joint>
    <joint name="left_ur_arm_shoulder_pan_joint" type="revolute">
        <parent link="left_ur_arm_base_link_inertia" />
        <child link="left_ur_arm_shoulder_link" />
        <origin rpy="0 0 0" xyz="0 0 0.1625" />
        <axis xyz="0 0 1" />
        <limit effort="150.0" lower="-6.28318530718" upper="6.28318530718" velocity="3.14159265359" />
        <dynamics damping="0" friction="0" />
    </joint>
    <joint name="left_ur_arm_shoulder_lift_joint" type="revolute">
        <parent link="left_ur_arm_shoulder_link" />
        <child link="left_ur_arm_upper_arm_link" />
        <origin rpy="1.570796327 0 0" xyz="0 0 0" />
        <axis xyz="0 0 1" />
        <limit effort="150.0" lower="-6.28318530718" upper="6.28318530718" velocity="3.14159265359" />
        <dynamics damping="0" friction="0" />
    </joint>
    <joint name="left_ur_arm_elbow_joint" type="revolute">
        <parent link="left_ur_arm_upper_arm_link" />
        <child link="left_ur_arm_forearm_link" />
        <origin rpy="0 0 0" xyz="-0.425 0 0" />
        <axis xyz="0 0 1" />
        <limit effort="150.0" lower="-3.14159265359" upper="3.14159265359" velocity="3.14159265359" />
        <dynamics damping="0" friction="0" />
    </joint>
    <joint name="left_ur_arm_wrist_1_joint" type="revolute">
        <parent link="left_ur_arm_forearm_link" />
        <child link="left_ur_arm_wrist_1_link" />
        <origin rpy="0 0 0" xyz="-0.3922 0 0.1333" />
        <axis xyz="0 0 1" />
        <limit effort="28.0" lower="-6.28318530718" upper="6.28318530718" velocity="3.14159265359" />
        <dynamics damping="0" friction="0" />
    </joint>
    <joint name="left_ur_arm_wrist_2_joint" type="revolute">
        <parent link="left_ur_arm_wrist_1_link" />
        <child link="left_ur_arm_wrist_2_link" />
        <origin rpy="1.570796327 0 0" xyz="0 -0.0997 -2.0448811823e-11" />
        <axis xyz="0 0 1" />
        <limit effort="28.0" lower="-6.28318530718" upper="6.28318530718" velocity="3.14159265359" />
        <dynamics damping="0" friction="0" />
    </joint>
    <joint name="left_ur_arm_wrist_3_joint" type="revolute">
        <parent link="left_ur_arm_wrist_2_link" />
        <child link="left_ur_arm_wrist_3_link" />
        <origin rpy="1.57079632659 3.14159265359 3.14159265359" xyz="0 0.0996 -2.04283014801e-11" />
        <axis xyz="0 0 1" />
        <limit effort="28.0" lower="-6.28318530718" upper="6.28318530718" velocity="3.14159265359" />
        <dynamics damping="0" friction="0" />
    </joint>
    <!-- ROS-Industrial 'base' frame: base_link to UR 'Base' Coordinates transform -->
    <link name="left_ur_arm_base" />
    <joint name="left_ur_arm_base_link-base_fixed_joint" type="fixed">
        <!-- Note the rotation over Z of pi radians: as base_link is REP-103
           aligned (ie: has X+ forward, Y+ left and Z+ up), this is needed
           to correctly align 'base' with the 'Base' coordinate system of
           the UR controller.
      -->
        <origin rpy="0 0 3.14159265359" xyz="0 0 0" />
        <parent link="left_ur_arm_base_link" />
        <child link="left_ur_arm_base" />
    </joint>
    <!-- ROS-Industrial 'flange' frame: attachment point for EEF models -->
    <link name="left_ur_arm_flange" />
    <joint name="left_ur_arm_wrist_3-flange" type="fixed">
        <parent link="left_ur_arm_wrist_3_link" />
        <child link="left_ur_arm_flange" />
        <origin rpy="0 -1.57079632679 -1.57079632679" xyz="0 0 0" />
    </joint>
    <!-- ROS-Industrial 'tool0' frame: all-zeros tool frame -->
    <link name="left_ur_arm_tool0" />
    <joint name="left_ur_arm_flange-tool0" type="fixed">
        <!-- default toolframe: X+ left, Y+ up, Z+ front -->
        <origin rpy="1.57079632679 0 1.57079632679" xyz="0 0 0" />
        <parent link="left_ur_arm_flange" />
        <child link="left_ur_arm_tool0" />
    </joint>
    <!-- This file is a placeholder which is included by default from
       husky.urdf.xacro. If a robot is being customized and requires
       additional URDF, set the HUSKY_URDF_EXTRAS environment variable
       to the full path of the file you would like included. -->
    <transmission name="trans_front_left_wheel">
        <type>transmission_interface/SimpleTransmission</type>
        <joint name="front_left_wheel">
            <hardwareInterface>hardware_interface/EffortJointInterface</hardwareInterface>
        </joint>
        <actuator name="front_left_wheel_motor">
            <hardwareInterface>hardware_interface/EffortJointInterface</hardwareInterface>
            <mechanicalReduction>1</mechanicalReduction>
        </actuator>
    </transmission>
    <transmission name="trans_front_right_wheel">
        <type>transmission_interface/SimpleTransmission</type>
        <joint name="front_right_wheel">
            <hardwareInterface>hardware_interface/EffortJointInterface</hardwareInterface>
        </joint>
        <actuator name="front_right_wheel_motor">
            <hardwareInterface>hardware_interface/EffortJointInterface</hardwareInterface>
            <mechanicalReduction>1</mechanicalReduction>
        </actuator>
    </transmission>
    <transmission name="trans_rear_left_wheel">
        <type>transmission_interface/SimpleTransmission</type>
        <joint name="rear_left_wheel">
            <hardwareInterface>hardware_interface/EffortJointInterface</hardwareInterface>
        </joint>
        <actuator name="rear_left_wheel_motor">
            <hardwareInterface>hardware_interface/EffortJointInterface</hardwareInterface>
            <mechanicalReduction>1</mechanicalReduction>
        </actuator>
    </transmission>
    <transmission name="trans_rear_right_wheel">
        <type>transmission_interface/SimpleTransmission</type>
        <joint name="rear_right_wheel">
            <hardwareInterface>hardware_interface/EffortJointInterface</hardwareInterface>
        </joint>
        <actuator name="rear_right_wheel_motor">
            <hardwareInterface>hardware_interface/EffortJointInterface</hardwareInterface>
            <mechanicalReduction>1</mechanicalReduction>
        </actuator>
    </transmission>
    <transmission name="trans_right_ur_arm_shoulder_pan_joint">
        <type>transmission_interface/SimpleTransmission</type>
        <joint name="right_ur_arm_shoulder_pan_joint">
            <hardwareInterface>hardware_interface/EffortJointInterface</hardwareInterface>
        </joint>
        <actuator name="right_ur_arm_shoulder_pan_joint_motor">
            <hardwareInterface>hardware_interface/EffortJointInterface</hardwareInterface>
            <mechanicalReduction>1</mechanicalReduction>
        </actuator>
    </transmission>
    <transmission name="trans_right_ur_arm_shoulder_lift_joint">
        <type>transmission_interface/SimpleTransmission</type>
        <joint name="right_ur_arm_shoulder_lift_joint">
            <hardwareInterface>hardware_interface/EffortJointInterface</hardwareInterface>
        </joint>
        <actuator name="right_ur_arm_shoulder_lift_joint_motor">
            <hardwareInterface>hardware_interface/EffortJointInterface</hardwareInterface>
            <mechanicalReduction>1</mechanicalReduction>
        </actuator>
    </transmission>
    <transmission name="trans_right_ur_arm_elbow_joint">
        <type>transmission_interface/SimpleTransmission</type>
        <joint name="right_ur_arm_elbow_joint">
            <hardwareInterface>hardware_interface/EffortJointInterface</hardwareInterface>
        </joint>
        <actuator name="right_ur_arm_elbow_joint_motor">
            <hardwareInterface>hardware_interface/EffortJointInterface</hardwareInterface>
            <mechanicalReduction>1</mechanicalReduction>
        </actuator>
    </transmission>
    <transmission name="trans_right_ur_arm_wrist_1_joint">
        <type>transmission_interface/SimpleTransmission</type>
        <joint name="right_ur_arm_wrist_1_joint">
            <hardwareInterface>hardware_interface/EffortJointInterface</hardwareInterface>
        </joint>
        <actuator name="right_ur_arm_wrist_1_joint_motor">
            <hardwareInterface>hardware_interface/EffortJointInterface</hardwareInterface>
            <mechanicalReduction>1</mechanicalReduction>
        </actuator>
    </transmission>
    <transmission name="trans_right_ur_arm_wrist_2_joint">
        <type>transmission_interface/SimpleTransmission</type>
        <joint name="right_ur_arm_wrist_2_joint">
            <hardwareInterface>hardware_interface/EffortJointInterface</hardwareInterface>
        </joint>
        <actuator name="right_ur_arm_wrist_2_joint_motor">
            <hardwareInterface>hardware_interface/EffortJointInterface</hardwareInterface>
            <mechanicalReduction>1</mechanicalReduction>
        </actuator>
    </transmission>
    <transmission name="trans_right_ur_arm_wrist_3_joint">
        <type>transmission_interface/SimpleTransmission</type>
        <joint name="right_ur_arm_wrist_3_joint">
            <hardwareInterface>hardware_interface/EffortJointInterface</hardwareInterface>
        </joint>
        <actuator name="right_ur_arm_wrist_3_joint_motor">
            <hardwareInterface>hardware_interface/EffortJointInterface</hardwareInterface>
            <mechanicalReduction>1</mechanicalReduction>
        </actuator>
    </transmission>
    <transmission name="trans_left_ur_arm_shoulder_pan_joint">
        <type>transmission_interface/SimpleTransmission</type>
        <joint name="left_ur_arm_shoulder_pan_joint">
            <hardwareInterface>hardware_interface/EffortJointInterface</hardwareInterface>
        </joint>
        <actuator name="left_ur_arm_shoulder_pan_joint_motor">
            <hardwareInterface>hardware_interface/EffortJointInterface</hardwareInterface>
            <mechanicalReduction>1</mechanicalReduction>
        </actuator>
    </transmission>
    <transmission name="trans_left_ur_arm_shoulder_lift_joint">
        <type>transmission_interface/SimpleTransmission</type>
        <joint name="left_ur_arm_shoulder_lift_joint">
            <hardwareInterface>hardware_interface/EffortJointInterface</hardwareInterface>
        </joint>
        <actuator name="left_ur_arm_shoulder_lift_joint_motor">
            <hardwareInterface>hardware_interface/EffortJointInterface</hardwareInterface>
            <mechanicalReduction>1</mechanicalReduction>
        </actuator>
    </transmission>
    <transmission name="trans_left_ur_arm_elbow_joint">
        <type>transmission_interface/SimpleTransmission</type>
        <joint name="left_ur_arm_elbow_joint">
            <hardwareInterface>hardware_interface/EffortJointInterface</hardwareInterface>
        </joint>
        <actuator name="left_ur_arm_elbow_joint_motor">
            <hardwareInterface>hardware_interface/EffortJointInterface</hardwareInterface>
            <mechanicalReduction>1</mechanicalReduction>
        </actuator>
    </transmission>
    <transmission name="trans_left_ur_arm_wrist_1_joint">
        <type>transmission_interface/SimpleTransmission</type>
        <joint name="left_ur_arm_wrist_1_joint">
            <hardwareInterface>hardware_interface/EffortJointInterface</hardwareInterface>
        </joint>
        <actuator name="left_ur_arm_wrist_1_joint_motor">
            <hardwareInterface>hardware_interface/EffortJointInterface</hardwareInterface>
            <mechanicalReduction>1</mechanicalReduction>
        </actuator>
    </transmission>
    <transmission name="trans_left_ur_arm_wrist_2_joint">
        <type>transmission_interface/SimpleTransmission</type>
        <joint name="left_ur_arm_wrist_2_joint">
            <hardwareInterface>hardware_interface/EffortJointInterface</hardwareInterface>
        </joint>
        <actuator name="left_ur_arm_wrist_2_joint_motor">
            <hardwareInterface>hardware_interface/EffortJointInterface</hardwareInterface>
            <mechanicalReduction>1</mechanicalReduction>
        </actuator>
    </transmission>
    <transmission name="trans_left_ur_arm_wrist_3_joint">
        <type>transmission_interface/SimpleTransmission</type>
        <joint name="left_ur_arm_wrist_3_joint">
            <hardwareInterface>hardware_interface/EffortJointInterface</hardwareInterface>
        </joint>
        <actuator name="left_ur_arm_wrist_3_joint_motor">
            <hardwareInterface>hardware_interface/EffortJointInterface</hardwareInterface>
            <mechanicalReduction>1</mechanicalReduction>
        </actuator>
    </transmission>
    <gazebo>
        <plugin name="gazebo_ros_control" filename="libgazebo_ros_control.so">
            <robotNamespace>/</robotNamespace>
        </plugin>
    </gazebo>
<!-- </robot> -->

<transmission name="front_left_wheel_trans" type="SimpleTransmission">
        <type>transmission_interface/SimpleTransmission</type>
        <actuator name="front_left_wheel_motor">
            <mechanicalReduction>1</mechanicalReduction>
        </actuator>
        <joint name="front_left_wheel">
            <hardwareInterface>hardware_interface/VelocityJointInterface</hardwareInterface>
        </joint>
</transmission>

    <link name="front_right_wheel_link">
        <inertial>
            <mass value="2.637" />
            <origin xyz="0 0 0" />
            <inertia ixx="0.02467" ixy="0" ixz="0" iyy="0.04411" iyz="0" izz="0.02467" />
        </inertial>
        <visual>
            <origin rpy="0 0 0" xyz="0 0 0" />
            <geometry>
                <mesh filename="package://husky_description/meshes/wheel.obj" />
            </geometry>
        </visual>
        <collision>
            <origin rpy="1.570795 0 0" xyz="0 0 0" />
            <geometry>
                <cylinder length="0.1143" radius="0.1651" />
            </geometry>
        </collision>
    </link>
    <gazebo reference="front_right_wheel_link">
        <mu1 value="1.0" />
        <mu2 value="1.0" />
        <kp value="10000000.0" />
        <kd value="1.0" />
        <fdir1 value="1 0 0" />
    </gazebo>
    <joint name="front_right_wheel" type="continuous">
        <parent link="base_link" />
        <child link="front_right_wheel_link" />
        <origin rpy="0 0 0" xyz="0.256 -0.2854 0.03282" />
        <axis rpy="0 0 0" xyz="0 1 0" />
    </joint>
    <transmission name="front_right_wheel_trans" type="SimpleTransmission">
        <type>transmission_interface/SimpleTransmission</type>
        <actuator name="front_right_wheel_motor">
            <mechanicalReduction>1</mechanicalReduction>
        </actuator>
        <joint name="front_right_wheel">
            <hardwareInterface>hardware_interface/VelocityJointInterface</hardwareInterface>
        </joint>
    </transmission>
    <link name="rear_left_wheel_link">
        <inertial>
            <mass value="2.637" />
            <origin xyz="0 0 0" />
            <inertia ixx="0.02467" ixy="0" ixz="0" iyy="0.04411" iyz="0" izz="0.02467" />
        </inertial>
        <visual>
            <origin rpy="0 0 0" xyz="0 0 0" />
            <geometry>
                <mesh filename="package://husky_description/meshes/wheel.obj" />
            </geometry>
        </visual>
        <collision>
            <origin rpy="1.570795 0 0" xyz="0 0 0" />
            <geometry>
                <cylinder length="0.1143" radius="0.1651" />
            </geometry>
        </collision>
    </link>
    <gazebo reference="rear_left_wheel_link">
        <mu1 value="1.0" />
        <mu2 value="1.0" />
        <kp value="10000000.0" />
        <kd value="1.0" />
        <fdir1 value="1 0 0" />
    </gazebo>
    <joint name="rear_left_wheel" type="continuous">
        <parent link="base_link" />
        <child link="rear_left_wheel_link" />
        <origin rpy="0 0 0" xyz="-0.256 0.2854 0.03282" />
        <axis rpy="0 0 0" xyz="0 1 0" />
    </joint>
    <transmission name="rear_left_wheel_trans" type="SimpleTransmission">
        <type>transmission_interface/SimpleTransmission</type>
        <actuator name="rear_left_wheel_motor">
            <mechanicalReduction>1</mechanicalReduction>
        </actuator>
        <joint name="rear_left_wheel">
            <hardwareInterface>hardware_interface/VelocityJointInterface</hardwareInterface>
        </joint>
    </transmission>
    <link name="rear_right_wheel_link">
        <inertial>
            <mass value="2.637" />
            <origin xyz="0 0 0" />
            <inertia ixx="0.02467" ixy="0" ixz="0" iyy="0.04411" iyz="0" izz="0.02467" />
        </inertial>
        <visual>
            <origin rpy="0 0 0" xyz="0 0 0" />
            <geometry>
                <mesh filename="package://husky_description/meshes/wheel.obj" />
            </geometry>
        </visual>
        <collision>
            <origin rpy="1.570795 0 0" xyz="0 0 0" />
            <geometry>
                <cylinder length="0.1143" radius="0.1651" />
            </geometry>
        </collision>
    </link>
    <gazebo reference="rear_right_wheel_link">
        <mu1 value="1.0" />
        <mu2 value="1.0" />
        <kp value="10000000.0" />
        <kd value="1.0" />
        <fdir1 value="1 0 0" />
    </gazebo>
    <joint name="rear_right_wheel" type="continuous">
        <parent link="base_link" />
        <child link="rear_right_wheel_link" />
        <origin rpy="0 0 0" xyz="-0.256 -0.2854 0.03282" />
        <axis rpy="0 0 0" xyz="0 1 0" />
    </joint>
    <transmission name="rear_right_wheel_trans" type="SimpleTransmission">
        <type>transmission_interface/SimpleTransmission</type>
        <actuator name="rear_right_wheel_motor">
            <mechanicalReduction>1</mechanicalReduction>
        </actuator>
        <joint name="rear_right_wheel">
            <hardwareInterface>hardware_interface/VelocityJointInterface</hardwareInterface>
        </joint>
    </transmission>
    <!-- Spawn Husky chassis -->
    <link name="top_chassis_link">
        <visual>
            <origin rpy="0 0 0" xyz="0 0 0" />
            <geometry>
                <mesh filename="package://husky_description/meshes/top_chassis.obj" />
            </geometry>
        </visual>
    </link>
    <!-- Attach chassis to the robot -->
    <joint name="top_chassis_joint" type="fixed">
        <parent link="base_link" />
        <child link="top_chassis_link" />
    </joint>
    <link name="front_bumper_link">
        <visual>
            <geometry>
                <mesh filename="package://husky_description/meshes/bumper.obj" />
            </geometry>
        </visual>
    </link>
    <!-- Attach front bumper -->
    <joint name="front_bumper" type="fixed">
        <origin rpy="0 0 0" xyz="0.48 0 0.091" />
        <parent link="base_link" />
        <child link="front_bumper_link" />
    </joint>
    <link name="rear_bumper_link">
        <visual>
            <geometry>
                <mesh filename="package://husky_description/meshes/bumper.obj" />
            </geometry>
        </visual>
    </link>
    <!-- Attach rear bumper -->
    <joint name="rear_bumper" type="fixed">
        <origin rpy="0 0 3.14159" xyz="-0.48 0 0.091" />
        <parent link="base_link" />
        <child link="rear_bumper_link" />
    </joint>
    <gazebo>
        <plugin filename="libgazebo_ros_control.so" name="gazebo_ros_control">
            <robotNamespace>/</robotNamespace>
            <legacyModeNS>true</legacyModeNS>
        </plugin>
    </gazebo>
    <gazebo>
        <plugin filename="libhector_gazebo_ros_imu.so" name="imu_controller">
            <robotNamespace>/</robotNamespace>
            <updateRate>50.0</updateRate>
            <bodyName>base_link</bodyName>
            <topicName>imu/data</topicName>
            <accelDrift>0.005 0.005 0.005</accelDrift>
            <accelGaussianNoise>0.005 0.005 0.005</accelGaussianNoise>
            <rateDrift>0.005 0.005 0.005</rateDrift>
            <rateGaussianNoise>0.005 0.005 0.005</rateGaussianNoise>
            <headingDrift>0.005</headingDrift>
            <headingGaussianNoise>0.005</headingGaussianNoise>
        </plugin>
    </gazebo>
    <gazebo>
        <plugin filename="libhector_gazebo_ros_gps.so" name="gps_controller">
            <robotNamespace>/</robotNamespace>
            <updateRate>40</updateRate>
            <bodyName>base_link</bodyName>
            <frameId>base_link</frameId>
            <topicName>navsat/fix</topicName>
            <velocityTopicName>navsat/vel</velocityTopicName>
            <referenceLatitude>49.9</referenceLatitude>
            <referenceLongitude>8.9</referenceLongitude>
            <referenceHeading>0</referenceHeading>
            <referenceAltitude>0</referenceAltitude>
            <drift>0.0001 0.0001 0.0001</drift>
        </plugin>
    </gazebo>
    <link name="dual_arm_bulkhead_link">
        <visual>
            <origin rpy="0 0 0" xyz="0 0 0" />
            <geometry>
                <mesh filename="package://husky_ur_description/meshes/dual_arm_bulkhead.obj" />
            </geometry>
        </visual>
        <collision>
            <origin rpy="0 0 0" xyz="0 0 0" />
            <geometry>
                <mesh filename="package://husky_ur_description/meshes/dual_arm_bulkhead_collision.stl" />
            </geometry>
        </collision>
        <inertial>
            <mass value="0.1" />
            <inertia ixx="0.03" iyy="0.03" izz="0.03" ixy="0.0" ixz="0.0" iyz="0.0" />
        </inertial>
    </link>
    <link name="left_arm_bulkhead_link" />
    <joint name="left_arm_bulkhead_joint" type="fixed">
        <parent link="dual_arm_bulkhead_link" />
        <child link="left_arm_bulkhead_link" />
        <origin rpy="0 -0.785398163397 -1.57079632679" xyz="0.1225 0.14891 0.13371" />
    </joint>
    <link name="right_arm_bulkhead_link" />
    <joint name="right_arm_bulkhead_joint" type="fixed">
        <parent link="dual_arm_bulkhead_link" />
        <child link="right_arm_bulkhead_link" />
        <origin rpy="0 0.785398163397 -1.57079632679" xyz="0.1225 -0.14891 0.13371" />
    </joint>

    <joint name="left_arm_mount_joint" type="fixed">
        <parent link="left_arm_bulkhead_link" />
        <child link="left_ur_arm_base_link" />
        <origin rpy="0 0 0" xyz="0 0 0" />
    </joint>
    <joint name="right_arm_mount_joint" type="fixed">
        <parent link="right_arm_bulkhead_link" />
        <child link="right_ur_arm_base_link" />
        <origin rpy="0 0 0" xyz="0 0 0" />
    </joint>
    <!--
    Base UR robot series xacro macro.

    NOTE: this is NOT a URDF. It cannot directly be loaded by consumers
    expecting a flattened '.urdf' file. See the top-level '.xacro' for that
    (but note: that .xacro must still be processed by the xacro command).

    For use in '.launch' files: use one of the 'load_urX.launch' convenience
    launch files.

    This file models the base kinematic chain of a UR robot, which then gets
    parameterised by various configuration files to convert it into a UR3(e),
    UR5(e), UR10(e) or UR16e.

    NOTE: the default kinematic parameters (ie: link lengths, frame locations,
    offets, etc) do not correspond to any particular robot. They are defaults
    only. There WILL be non-zero offsets between the Forward Kinematics results
    in TF (ie: robot_state_publisher) and the values reported by the Teach
    Pendant.

    For accurate (and robot-specific) transforms, the 'kinematics_parameters_file'
    parameter MUST point to a .yaml file containing the appropriate values for
    the targetted robot.

    If using the UniversalRobots/Universal_Robots_ROS_Driver, follow the steps
    described in the readme of that repository to extract the kinematic
    calibration from the controller and generate the required .yaml file.

    Main author of the migration to yaml configs: Ludovic Delval.

    Contributors to previous versions (in no particular order):

     - Felix Messmer
     - Kelsey Hawkins
     - Wim Meeussen
     - Shaun Edwards
     - Nadia Hammoudeh Garcia
     - Dave Hershberger
     - G. vd. Hoorn
     - Philip Long
     - Dave Coleman
     - Miguel Prada
     - Mathias Luedtke
     - Marcel Schnirring
     - Felix von Drigalski
     - Felix Exner
     - Jimmy Da Silva
     - Ajit Krisshna N L
     - Muhammad Asif Rana
  -->
    <!--
    NOTE: the macro defined in this file is NOT part of the public API of this
          package. Users CANNOT rely on this file being available, or stored in
          this location. Nor can they rely on the existence of the macro.
  -->
    <transmission name="right_ur_arm_shoulder_pan_trans">
        <type>transmission_interface/SimpleTransmission</type>
        <joint name="right_ur_arm_shoulder_pan_joint">
            <hardwareInterface>hardware_interface/PositionJointInterface</hardwareInterface>
        </joint>
        <actuator name="right_ur_arm_shoulder_pan_motor">
            <mechanicalReduction>1</mechanicalReduction>
        </actuator>
    </transmission>
    <transmission name="right_ur_arm_shoulder_lift_trans">
        <type>transmission_interface/SimpleTransmission</type>
        <joint name="right_ur_arm_shoulder_lift_joint">
            <hardwareInterface>hardware_interface/PositionJointInterface</hardwareInterface>
        </joint>
        <actuator name="right_ur_arm_shoulder_lift_motor">
            <mechanicalReduction>1</mechanicalReduction>
        </actuator>
    </transmission>
    <transmission name="right_ur_arm_elbow_trans">
        <type>transmission_interface/SimpleTransmission</type>
        <joint name="right_ur_arm_elbow_joint">
            <hardwareInterface>hardware_interface/PositionJointInterface</hardwareInterface>
        </joint>
        <actuator name="right_ur_arm_elbow_motor">
            <mechanicalReduction>1</mechanicalReduction>
        </actuator>
    </transmission>
    <transmission name="right_ur_arm_wrist_1_trans">
        <type>transmission_interface/SimpleTransmission</type>
        <joint name="right_ur_arm_wrist_1_joint">
            <hardwareInterface>hardware_interface/PositionJointInterface</hardwareInterface>
        </joint>
        <actuator name="right_ur_arm_wrist_1_motor">
            <mechanicalReduction>1</mechanicalReduction>
        </actuator>
    </transmission>
    <transmission name="right_ur_arm_wrist_2_trans">
        <type>transmission_interface/SimpleTransmission</type>
        <joint name="right_ur_arm_wrist_2_joint">
            <hardwareInterface>hardware_interface/PositionJointInterface</hardwareInterface>
        </joint>
        <actuator name="right_ur_arm_wrist_2_motor">
            <mechanicalReduction>1</mechanicalReduction>
        </actuator>
    </transmission>
    <transmission name="right_ur_arm_wrist_3_trans">
        <type>transmission_interface/SimpleTransmission</type>
        <joint name="right_ur_arm_wrist_3_joint">
            <hardwareInterface>hardware_interface/PositionJointInterface</hardwareInterface>
        </joint>
        <actuator name="right_ur_arm_wrist_3_motor">
            <mechanicalReduction>1</mechanicalReduction>
        </actuator>
    </transmission>

    <!-- links: main serial chain -->
    <link name="right_ur_arm_base_link" />
    <link name="right_ur_arm_base_link_inertia">
        <visual>
            <origin rpy="0 0 3.14159265359" xyz="0 0 0" />
            <geometry>
                <mesh filename="package://ur_description/meshes/ur5e/visual/base.obj" />
            </geometry>
            <material name="LightGrey">
                <color rgba="0.7 0.7 0.7 1.0" />
            </material>
        </visual>
        <collision>
            <origin rpy="0 0 3.14159265359" xyz="0 0 0" />
            <geometry>
                <mesh filename="package://ur_description/meshes/ur5e/collision/base.stl" />
            </geometry>
        </collision>
        <inertial>
            <mass value="4.0" />
            <origin rpy="0 0 0" xyz="0 0 0" />
            <inertia ixx="0.00443333156" ixy="0.0" ixz="0.0" iyy="0.00443333156" iyz="0.0" izz="0.0072" />
        </inertial>
    </link>
    <link name="right_ur_arm_shoulder_link">
        <visual>
            <origin rpy="0 0 3.14159265359" xyz="0 0 0" />
            <geometry>
                <mesh filename="package://ur_description/meshes/ur5e/visual/shoulder.obj" />
            </geometry>
            <material name="LightGrey">
                <color rgba="0.7 0.7 0.7 1.0" />
            </material>
        </visual>
        <collision>
            <origin rpy="0 0 3.14159265359" xyz="0 0 0" />
            <geometry>
                <mesh filename="package://ur_description/meshes/ur5e/collision/shoulder.stl" />
            </geometry>
        </collision>
        <inertial>
            <mass value="3.7" />
            <origin rpy="0 0 0" xyz="0 0 0" />
            <inertia ixx="0.010267495893" ixy="0.0" ixz="0.0" iyy="0.010267495893" iyz="0.0" izz="0.00666" />
        </inertial>
    </link>
    <link name="right_ur_arm_upper_arm_link">
        <visual>
            <origin rpy="1.57079632679 0 -1.57079632679" xyz="0 0 0.138" />
            <geometry>
                <mesh filename="package://ur_description/meshes/ur5e/visual/upperarm.obj" />
            </geometry>
            <material name="LightGrey">
                <color rgba="0.7 0.7 0.7 1.0" />
            </material>
        </visual>
        <collision>
            <origin rpy="1.57079632679 0 -1.57079632679" xyz="0 0 0.138" />
            <geometry>
                <mesh filename="package://ur_description/meshes/ur5e/collision/upperarm.stl" />
            </geometry>
        </collision>
        <inertial>
            <mass value="8.393" />
            <origin rpy="0 1.57079632679 0" xyz="-0.2125 0.0 0.138" />
            <inertia ixx="0.133885781862" ixy="0.0" ixz="0.0" iyy="0.133885781862" iyz="0.0" izz="0.0151074" />
        </inertial>
    </link>
    <link name="right_ur_arm_forearm_link">
        <visual>
            <origin rpy="1.57079632679 0 -1.57079632679" xyz="0 0 0.007" />
            <geometry>
                <mesh filename="package://ur_description/meshes/ur5e/visual/forearm.obj" />
            </geometry>
            <material name="LightGrey">
                <color rgba="0.7 0.7 0.7 1.0" />
            </material>
        </visual>
        <collision>
            <origin rpy="1.57079632679 0 -1.57079632679" xyz="0 0 0.007" />
            <geometry>
                <mesh filename="package://ur_description/meshes/ur5e/collision/forearm.stl" />
            </geometry>
        </collision>
        <inertial>
            <mass value="2.275" />
            <origin rpy="0 1.57079632679 0" xyz="-0.1961 0.0 0.007" />
            <inertia ixx="0.0312093550996" ixy="0.0" ixz="0.0" iyy="0.0312093550996" iyz="0.0" izz="0.004095" />
        </inertial>
    </link>
    <link name="right_ur_arm_wrist_1_link">
        <visual>
            <!-- TODO: Move this to a parameter -->
            <origin rpy="1.57079632679 0 0" xyz="0 0 -0.127" />
            <geometry>
                <mesh filename="package://ur_description/meshes/ur5e/visual/wrist1.obj" />
            </geometry>
            <material name="LightGrey">
                <color rgba="0.7 0.7 0.7 1.0" />
            </material>
        </visual>
        <collision>
            <origin rpy="1.57079632679 0 0" xyz="0 0 -0.127" />
            <geometry>
                <mesh filename="package://ur_description/meshes/ur5e/collision/wrist1.stl" />
            </geometry>
        </collision>
        <inertial>
            <mass value="1.219" />
            <origin rpy="0 0 0" xyz="0 0 0" />
            <inertia ixx="0.00255989897604" ixy="0.0" ixz="0.0" iyy="0.00255989897604" iyz="0.0" izz="0.0021942" />
        </inertial>
    </link>
    <link name="right_ur_arm_wrist_2_link">
        <visual>
            <origin rpy="0 0 0" xyz="0 0 -0.0997" />
            <geometry>
                <mesh filename="package://ur_description/meshes/ur5e/visual/wrist2.obj" />
            </geometry>
            <material name="LightGrey">
                <color rgba="0.7 0.7 0.7 1.0" />
            </material>
        </visual>
        <collision>
            <origin rpy="0 0 0" xyz="0 0 -0.0997" />
            <geometry>
                <mesh filename="package://ur_description/meshes/ur5e/collision/wrist2.stl" />
            </geometry>
        </collision>
        <inertial>
            <mass value="1.219" />
            <origin rpy="0 0 0" xyz="0 0 0" />
            <inertia ixx="0.00255989897604" ixy="0.0" ixz="0.0" iyy="0.00255989897604" iyz="0.0" izz="0.0021942" />
        </inertial>
    </link>
    <link name="right_ur_arm_wrist_3_link">
        <visual>
            <origin rpy="1.57079632679 0 0" xyz="0 0 -0.0989" />
            <geometry>
                <mesh filename="package://ur_description/meshes/ur5e/visual/wrist3.obj" />
            </geometry>
            <material name="LightGrey">
                <color rgba="0.7 0.7 0.7 1.0" />
            </material>
        </visual>
        <collision>
            <origin rpy="1.57079632679 0 0" xyz="0 0 -0.0989" />
            <geometry>
                <mesh filename="package://ur_description/meshes/ur5e/collision/wrist3.stl" />
            </geometry>
        </collision>
        <inertial>
            <mass value="0.1879" />
            <origin rpy="0 0 0" xyz="0.0 0.0 -0.0229" />
            <inertia ixx="9.89041005217e-05" ixy="0.0" ixz="0.0" iyy="9.89041005217e-05" iyz="0.0" izz="0.0001321171875" />
        </inertial>
    </link>
    <!-- joints: main serial chain -->
    <joint name="right_ur_arm_base_link-base_link_inertia" type="fixed">
        <parent link="right_ur_arm_base_link" />
        <child link="right_ur_arm_base_link_inertia" />
        <!-- 'base_link' is REP-103 aligned (so X+ forward), while the internal
           frames of the robot/controller have X+ pointing backwards.
           Use the joint between 'base_link' and 'base_link_inertia' (a dummy
           link/frame) to introduce the necessary rotation over Z (of pi rad).
      -->
        <origin rpy="0 0 3.14159265359" xyz="0 0 0" />
    </joint>
    <joint name="right_ur_arm_shoulder_pan_joint" type="revolute">
        <parent link="right_ur_arm_base_link_inertia" />
        <child link="right_ur_arm_shoulder_link" />
        <origin rpy="0 0 0" xyz="0 0 0.1625" />
        <axis xyz="0 0 1" />
        <limit effort="150.0" lower="-6.28318530718" upper="6.28318530718" velocity="3.14159265359" />
        <dynamics damping="0" friction="0" />
    </joint>
    <joint name="right_ur_arm_shoulder_lift_joint" type="revolute">
        <parent link="right_ur_arm_shoulder_link" />
        <child link="right_ur_arm_upper_arm_link" />
        <origin rpy="1.570796327 0 0" xyz="0 0 0" />
        <axis xyz="0 0 1" />
        <limit effort="150.0" lower="-6.28318530718" upper="6.28318530718" velocity="3.14159265359" />
        <dynamics damping="0" friction="0" />
    </joint>
    <joint name="right_ur_arm_elbow_joint" type="revolute">
        <parent link="right_ur_arm_upper_arm_link" />
        <child link="right_ur_arm_forearm_link" />
        <origin rpy="0 0 0" xyz="-0.425 0 0" />
        <axis xyz="0 0 1" />
        <limit effort="150.0" lower="-3.14159265359" upper="3.14159265359" velocity="3.14159265359" />
        <dynamics damping="0" friction="0" />
    </joint>
    <joint name="right_ur_arm_wrist_1_joint" type="revolute">
        <parent link="right_ur_arm_forearm_link" />
        <child link="right_ur_arm_wrist_1_link" />
        <origin rpy="0 0 0" xyz="-0.3922 0 0.1333" />
        <axis xyz="0 0 1" />
        <limit effort="28.0" lower="-6.28318530718" upper="6.28318530718" velocity="3.14159265359" />
        <dynamics damping="0" friction="0" />
    </joint>
    <joint name="right_ur_arm_wrist_2_joint" type="revolute">
        <parent link="right_ur_arm_wrist_1_link" />
        <child link="right_ur_arm_wrist_2_link" />
        <origin rpy="1.570796327 0 0" xyz="0 -0.0997 -2.0448811823e-11" />
        <axis xyz="0 0 1" />
        <limit effort="28.0" lower="-6.28318530718" upper="6.28318530718" velocity="3.14159265359" />
        <dynamics damping="0" friction="0" />
    </joint>
    <joint name="right_ur_arm_wrist_3_joint" type="revolute">
        <parent link="right_ur_arm_wrist_2_link" />
        <child link="right_ur_arm_wrist_3_link" />
        <origin rpy="1.57079632659 3.14159265359 3.14159265359" xyz="0 0.0996 -2.04283014801e-11" />
        <axis xyz="0 0 1" />
        <limit effort="28.0" lower="-6.28318530718" upper="6.28318530718" velocity="3.14159265359" />
        <dynamics damping="0" friction="0" />
    </joint>
    <!-- ROS-Industrial 'base' frame: base_link to UR 'Base' Coordinates transform -->
    <link name="right_ur_arm_base" />
    <joint name="right_ur_arm_base_link-base_fixed_joint" type="fixed">
        <!-- Note the rotation over Z of pi radians: as base_link is REP-103
           aligned (ie: has X+ forward, Y+ left and Z+ up), this is needed
           to correctly align 'base' with the 'Base' coordinate system of
           the UR controller.
      -->
        <origin rpy="0 0 3.14159265359" xyz="0 0 0" />
        <parent link="right_ur_arm_base_link" />
        <child link="right_ur_arm_base" />
    </joint>
    <!-- ROS-Industrial 'flange' frame: attachment point for EEF models -->
    <link name="right_ur_arm_flange" />
    <joint name="right_ur_arm_wrist_3-flange" type="fixed">
        <parent link="right_ur_arm_wrist_3_link" />
        <child link="right_ur_arm_flange" />
        <origin rpy="0 -1.57079632679 -1.57079632679" xyz="0 0 0" />
    </joint>
    <!-- ROS-Industrial 'tool0' frame: all-zeros tool frame -->
    <link name="right_ur_arm_tool0" />
    <joint name="right_ur_arm_flange-tool0" type="fixed">
        <!-- default toolframe: X+ left, Y+ up, Z+ front -->
        <origin rpy="1.57079632679 0 1.57079632679" xyz="0 0 0" />
        <parent link="right_ur_arm_flange" />
        <child link="right_ur_arm_tool0" />
    </joint>

    <!--
    Base UR robot series xacro macro.

    NOTE: this is NOT a URDF. It cannot directly be loaded by consumers
    expecting a flattened '.urdf' file. See the top-level '.xacro' for that
    (but note: that .xacro must still be processed by the xacro command).

    For use in '.launch' files: use one of the 'load_urX.launch' convenience
    launch files.

    This file models the base kinematic chain of a UR robot, which then gets
    parameterised by various configuration files to convert it into a UR3(e),
    UR5(e), UR10(e) or UR16e.

    NOTE: the default kinematic parameters (ie: link lengths, frame locations,
    offets, etc) do not correspond to any particular robot. They are defaults
    only. There WILL be non-zero offsets between the Forward Kinematics results
    in TF (ie: robot_state_publisher) and the values reported by the Teach
    Pendant.

    For accurate (and robot-specific) transforms, the 'kinematics_parameters_file'
    parameter MUST point to a .yaml file containing the appropriate values for
    the targetted robot.

    If using the UniversalRobots/Universal_Robots_ROS_Driver, follow the steps
    described in the readme of that repository to extract the kinematic
    calibration from the controller and generate the required .yaml file.

    Main author of the migration to yaml configs: Ludovic Delval.

    Contributors to previous versions (in no particular order):

     - Felix Messmer
     - Kelsey Hawkins
     - Wim Meeussen
     - Shaun Edwards
     - Nadia Hammoudeh Garcia
     - Dave Hershberger
     - G. vd. Hoorn
     - Philip Long
     - Dave Coleman
     - Miguel Prada
     - Mathias Luedtke
     - Marcel Schnirring
     - Felix von Drigalski
     - Felix Exner
     - Jimmy Da Silva
     - Ajit Krisshna N L
     - Muhammad Asif Rana
  -->
    <!--
    NOTE: the macro defined in this file is NOT part of the public API of this
          package. Users CANNOT rely on this file being available, or stored in
          this location. Nor can they rely on the existence of the macro.
  -->
    <transmission name="left_ur_arm_shoulder_pan_trans">
        <type>transmission_interface/SimpleTransmission</type>
        <joint name="left_ur_arm_shoulder_pan_joint">
            <hardwareInterface>hardware_interface/PositionJointInterface</hardwareInterface>
        </joint>
        <actuator name="left_ur_arm_shoulder_pan_motor">
            <mechanicalReduction>1</mechanicalReduction>
        </actuator>
    </transmission>
    <transmission name="left_ur_arm_shoulder_lift_trans">
        <type>transmission_interface/SimpleTransmission</type>
        <joint name="left_ur_arm_shoulder_lift_joint">
            <hardwareInterface>hardware_interface/PositionJointInterface</hardwareInterface>
        </joint>
        <actuator name="left_ur_arm_shoulder_lift_motor">
            <mechanicalReduction>1</mechanicalReduction>
        </actuator>
    </transmission>
    <transmission name="left_ur_arm_elbow_trans">
        <type>transmission_interface/SimpleTransmission</type>
        <joint name="left_ur_arm_elbow_joint">
            <hardwareInterface>hardware_interface/PositionJointInterface</hardwareInterface>
        </joint>
        <actuator name="left_ur_arm_elbow_motor">
            <mechanicalReduction>1</mechanicalReduction>
        </actuator>
    </transmission>
    <transmission name="left_ur_arm_wrist_1_trans">
        <type>transmission_interface/SimpleTransmission</type>
        <joint name="left_ur_arm_wrist_1_joint">
            <hardwareInterface>hardware_interface/PositionJointInterface</hardwareInterface>
        </joint>
        <actuator name="left_ur_arm_wrist_1_motor">
            <mechanicalReduction>1</mechanicalReduction>
        </actuator>
    </transmission>
    <transmission name="left_ur_arm_wrist_2_trans">
        <type>transmission_interface/SimpleTransmission</type>
        <joint name="left_ur_arm_wrist_2_joint">
            <hardwareInterface>hardware_interface/PositionJointInterface</hardwareInterface>
        </joint>
        <actuator name="left_ur_arm_wrist_2_motor">
            <mechanicalReduction>1</mechanicalReduction>
        </actuator>
    </transmission>
    <transmission name="left_ur_arm_wrist_3_trans">
        <type>transmission_interface/SimpleTransmission</type>
        <joint name="left_ur_arm_wrist_3_joint">
            <hardwareInterface>hardware_interface/PositionJointInterface</hardwareInterface>
        </joint>
        <actuator name="left_ur_arm_wrist_3_motor">
            <mechanicalReduction>1</mechanicalReduction>
        </actuator>
    </transmission>
    <!-- links: main serial chain -->
    <link name="left_ur_arm_base_link" />
    <link name="left_ur_arm_base_link_inertia">
        <visual>
            <origin rpy="0 0 3.14159265359" xyz="0 0 0" />
            <geometry>
                <mesh filename="package://ur_description/meshes/ur5e/visual/base.obj" />
            </geometry>
            <material name="LightGrey">
                <color rgba="0.7 0.7 0.7 1.0" />
            </material>
        </visual>
        <collision>
            <origin rpy="0 0 3.14159265359" xyz="0 0 0" />
            <geometry>
                <mesh filename="package://ur_description/meshes/ur5e/collision/base.stl" />
            </geometry>
        </collision>
        <inertial>
            <mass value="4.0" />
            <origin rpy="0 0 0" xyz="0 0 0" />
            <inertia ixx="0.00443333156" ixy="0.0" ixz="0.0" iyy="0.00443333156" iyz="0.0" izz="0.0072" />
        </inertial>
    </link>
    <link name="left_ur_arm_shoulder_link">
        <visual>
            <origin rpy="0 0 3.14159265359" xyz="0 0 0" />
            <geometry>
                <mesh filename="package://ur_description/meshes/ur5e/visual/shoulder.obj" />
            </geometry>
            <material name="LightGrey">
                <color rgba="0.7 0.7 0.7 1.0" />
            </material>
        </visual>
        <collision>
            <origin rpy="0 0 3.14159265359" xyz="0 0 0" />
            <geometry>
                <mesh filename="package://ur_description/meshes/ur5e/collision/shoulder.stl" />
            </geometry>
        </collision>
        <inertial>
            <mass value="3.7" />
            <origin rpy="0 0 0" xyz="0 0 0" />
            <inertia ixx="0.010267495893" ixy="0.0" ixz="0.0" iyy="0.010267495893" iyz="0.0" izz="0.00666" />
        </inertial>
    </link>
    <link name="left_ur_arm_upper_arm_link">
        <visual>
            <origin rpy="1.57079632679 0 -1.57079632679" xyz="0 0 0.138" />
            <geometry>
                <mesh filename="package://ur_description/meshes/ur5e/visual/upperarm.obj" />
            </geometry>
            <material name="LightGrey">
                <color rgba="0.7 0.7 0.7 1.0" />
            </material>
        </visual>
        <collision>
            <origin rpy="1.57079632679 0 -1.57079632679" xyz="0 0 0.138" />
            <geometry>
                <mesh filename="package://ur_description/meshes/ur5e/collision/upperarm.stl" />
            </geometry>
        </collision>
        <inertial>
            <mass value="8.393" />
            <origin rpy="0 1.57079632679 0" xyz="-0.2125 0.0 0.138" />
            <inertia ixx="0.133885781862" ixy="0.0" ixz="0.0" iyy="0.133885781862" iyz="0.0" izz="0.0151074" />
        </inertial>
    </link>
    <link name="left_ur_arm_forearm_link">
        <visual>
            <origin rpy="1.57079632679 0 -1.57079632679" xyz="0 0 0.007" />
            <geometry>
                <mesh filename="package://ur_description/meshes/ur5e/visual/forearm.obj" />
            </geometry>
            <material name="LightGrey">
                <color rgba="0.7 0.7 0.7 1.0" />
            </material>
        </visual>
        <collision>
            <origin rpy="1.57079632679 0 -1.57079632679" xyz="0 0 0.007" />
            <geometry>
                <mesh filename="package://ur_description/meshes/ur5e/collision/forearm.stl" />
            </geometry>
        </collision>
        <inertial>
            <mass value="2.275" />
            <origin rpy="0 1.57079632679 0" xyz="-0.1961 0.0 0.007" />
            <inertia ixx="0.0312093550996" ixy="0.0" ixz="0.0" iyy="0.0312093550996" iyz="0.0" izz="0.004095" />
        </inertial>
    </link>
    <link name="left_ur_arm_wrist_1_link">
        <visual>
            <!-- TODO: Move this to a parameter -->
            <origin rpy="1.57079632679 0 0" xyz="0 0 -0.127" />
            <geometry>
                <mesh filename="package://ur_description/meshes/ur5e/visual/wrist1.obj" />
            </geometry>
            <material name="LightGrey">
                <color rgba="0.7 0.7 0.7 1.0" />
            </material>
        </visual>
        <collision>
            <origin rpy="1.57079632679 0 0" xyz="0 0 -0.127" />
            <geometry>
                <mesh filename="package://ur_description/meshes/ur5e/collision/wrist1.stl" />
            </geometry>
        </collision>
        <inertial>
            <mass value="1.219" />
            <origin rpy="0 0 0" xyz="0 0 0" />
            <inertia ixx="0.00255989897604" ixy="0.0" ixz="0.0" iyy="0.00255989897604" iyz="0.0" izz="0.0021942" />
        </inertial>
    </link>
    <link name="left_ur_arm_wrist_2_link">
        <visual>
            <origin rpy="0 0 0" xyz="0 0 -0.0997" />
            <geometry>
                <mesh filename="package://ur_description/meshes/ur5e/visual/wrist2.obj" />
            </geometry>
            <material name="LightGrey">
                <color rgba="0.7 0.7 0.7 1.0" />
            </material>
        </visual>
        <collision>
            <origin rpy="0 0 0" xyz="0 0 -0.0997" />
            <geometry>
                <mesh filename="package://ur_description/meshes/ur5e/collision/wrist2.stl" />
            </geometry>
        </collision>
        <inertial>
            <mass value="1.219" />
            <origin rpy="0 0 0" xyz="0 0 0" />
            <inertia ixx="0.00255989897604" ixy="0.0" ixz="0.0" iyy="0.00255989897604" iyz="0.0" izz="0.0021942" />
        </inertial>
    </link>
    <link name="left_ur_arm_wrist_3_link">
        <visual>
            <origin rpy="1.57079632679 0 0" xyz="0 0 -0.0989" />
            <geometry>
                <mesh filename="package://ur_description/meshes/ur5e/visual/wrist3.obj" />
            </geometry>
            <material name="LightGrey">
                <color rgba="0.7 0.7 0.7 1.0" />
            </material>
        </visual>
        <collision>
            <origin rpy="1.57079632679 0 0" xyz="0 0 -0.0989" />
            <geometry>
                <mesh filename="package://ur_description/meshes/ur5e/collision/wrist3.stl" />
            </geometry>
        </collision>
        <inertial>
            <mass value="0.1879" />
            <origin rpy="0 0 0" xyz="0.0 0.0 -0.0229" />
            <inertia ixx="9.89041005217e-05" ixy="0.0" ixz="0.0" iyy="9.89041005217e-05" iyz="0.0" izz="0.0001321171875" />
        </inertial>
    </link>
    <!-- joints: main serial chain -->
    <joint name="left_ur_arm_base_link-base_link_inertia" type="fixed">
        <parent link="left_ur_arm_base_link" />
        <child link="left_ur_arm_base_link_inertia" />
        <!-- 'base_link' is REP-103 aligned (so X+ forward), while the internal
           frames of the robot/controller have X+ pointing backwards.
           Use the joint between 'base_link' and 'base_link_inertia' (a dummy
           link/frame) to introduce the necessary rotation over Z (of pi rad).
      -->
        <origin rpy="0 0 3.14159265359" xyz="0 0 0" />
    </joint>
    <joint name="left_ur_arm_shoulder_pan_joint" type="revolute">
        <parent link="left_ur_arm_base_link_inertia" />
        <child link="left_ur_arm_shoulder_link" />
        <origin rpy="0 0 0" xyz="0 0 0.1625" />
        <axis xyz="0 0 1" />
        <limit effort="150.0" lower="-6.28318530718" upper="6.28318530718" velocity="3.14159265359" />
        <dynamics damping="0" friction="0" />
    </joint>
    <joint name="left_ur_arm_shoulder_lift_joint" type="revolute">
        <parent link="left_ur_arm_shoulder_link" />
        <child link="left_ur_arm_upper_arm_link" />
        <origin rpy="1.570796327 0 0" xyz="0 0 0" />
        <axis xyz="0 0 1" />
        <limit effort="150.0" lower="-6.28318530718" upper="6.28318530718" velocity="3.14159265359" />
        <dynamics damping="0" friction="0" />
    </joint>
    <joint name="left_ur_arm_elbow_joint" type="revolute">
        <parent link="left_ur_arm_upper_arm_link" />
        <child link="left_ur_arm_forearm_link" />
        <origin rpy="0 0 0" xyz="-0.425 0 0" />
        <axis xyz="0 0 1" />
        <limit effort="150.0" lower="-3.14159265359" upper="3.14159265359" velocity="3.14159265359" />
        <dynamics damping="0" friction="0" />
    </joint>
    <joint name="left_ur_arm_wrist_1_joint" type="revolute">
        <parent link="left_ur_arm_forearm_link" />
        <child link="left_ur_arm_wrist_1_link" />
        <origin rpy="0 0 0" xyz="-0.3922 0 0.1333" />
        <axis xyz="0 0 1" />
        <limit effort="28.0" lower="-6.28318530718" upper="6.28318530718" velocity="3.14159265359" />
        <dynamics damping="0" friction="0" />
    </joint>
    <joint name="left_ur_arm_wrist_2_joint" type="revolute">
        <parent link="left_ur_arm_wrist_1_link" />
        <child link="left_ur_arm_wrist_2_link" />
        <origin rpy="1.570796327 0 0" xyz="0 -0.0997 -2.0448811823e-11" />
        <axis xyz="0 0 1" />
        <limit effort="28.0" lower="-6.28318530718" upper="6.28318530718" velocity="3.14159265359" />
        <dynamics damping="0" friction="0" />
    </joint>
    <joint name="left_ur_arm_wrist_3_joint" type="revolute">
        <parent link="left_ur_arm_wrist_2_link" />
        <child link="left_ur_arm_wrist_3_link" />
        <origin rpy="1.57079632659 3.14159265359 3.14159265359" xyz="0 0.0996 -2.04283014801e-11" />
        <axis xyz="0 0 1" />
        <limit effort="28.0" lower="-6.28318530718" upper="6.28318530718" velocity="3.14159265359" />
        <dynamics damping="0" friction="0" />
    </joint>
    <!-- ROS-Industrial 'base' frame: base_link to UR 'Base' Coordinates transform -->
    <link name="left_ur_arm_base" />
    <joint name="left_ur_arm_base_link-base_fixed_joint" type="fixed">
        <!-- Note the rotation over Z of pi radians: as base_link is REP-103
           aligned (ie: has X+ forward, Y+ left and Z+ up), this is needed
           to correctly align 'base' with the 'Base' coordinate system of
           the UR controller.
      -->
        <origin rpy="0 0 3.14159265359" xyz="0 0 0" />
        <parent link="left_ur_arm_base_link" />
        <child link="left_ur_arm_base" />
    </joint>
    <!-- ROS-Industrial 'flange' frame: attachment point for EEF models -->
    <link name="left_ur_arm_flange" />
    <joint name="left_ur_arm_wrist_3-flange" type="fixed">
        <parent link="left_ur_arm_wrist_3_link" />
        <child link="left_ur_arm_flange" />
        <origin rpy="0 -1.57079632679 -1.57079632679" xyz="0 0 0" />
    </joint>
    <!-- ROS-Industrial 'tool0' frame: all-zeros tool frame -->
    <link name="left_ur_arm_tool0" />
    <joint name="left_ur_arm_flange-tool0" type="fixed">
        <!-- default toolframe: X+ left, Y+ up, Z+ front -->
        <origin rpy="1.57079632679 0 1.57079632679" xyz="0 0 0" />
        <parent link="left_ur_arm_flange" />
        <child link="left_ur_arm_tool0" />
    </joint>
    <!-- This file is a placeholder which is included by default from
       husky.urdf.xacro. If a robot is being customized and requires
       additional URDF, set the HUSKY_URDF_EXTRAS environment variable
       to the full path of the file you would like included. -->
    <transmission name="trans_front_left_wheel">
        <type>transmission_interface/SimpleTransmission</type>
        <joint name="front_left_wheel">
            <hardwareInterface>hardware_interface/EffortJointInterface</hardwareInterface>
        </joint>
        <actuator name="front_left_wheel_motor">
            <hardwareInterface>hardware_interface/EffortJointInterface</hardwareInterface>
            <mechanicalReduction>1</mechanicalReduction>
        </actuator>
    </transmission>
    <transmission name="trans_front_right_wheel">
        <type>transmission_interface/SimpleTransmission</type>
        <joint name="front_right_wheel">
            <hardwareInterface>hardware_interface/EffortJointInterface</hardwareInterface>
        </joint>
        <actuator name="front_right_wheel_motor">
            <hardwareInterface>hardware_interface/EffortJointInterface</hardwareInterface>
            <mechanicalReduction>1</mechanicalReduction>
        </actuator>
    </transmission>
    <transmission name="trans_rear_left_wheel">
        <type>transmission_interface/SimpleTransmission</type>
        <joint name="rear_left_wheel">
            <hardwareInterface>hardware_interface/EffortJointInterface</hardwareInterface>
        </joint>
        <actuator name="rear_left_wheel_motor">
            <hardwareInterface>hardware_interface/EffortJointInterface</hardwareInterface>
            <mechanicalReduction>1</mechanicalReduction>
        </actuator>
    </transmission>
    <transmission name="trans_rear_right_wheel">
        <type>transmission_interface/SimpleTransmission</type>
        <joint name="rear_right_wheel">
            <hardwareInterface>hardware_interface/EffortJointInterface</hardwareInterface>
        </joint>
        <actuator name="rear_right_wheel_motor">
            <hardwareInterface>hardware_interface/EffortJointInterface</hardwareInterface>
            <mechanicalReduction>1</mechanicalReduction>
        </actuator>
    </transmission>
    <transmission name="trans_right_ur_arm_shoulder_pan_joint">
        <type>transmission_interface/SimpleTransmission</type>
        <joint name="right_ur_arm_shoulder_pan_joint">
            <hardwareInterface>hardware_interface/EffortJointInterface</hardwareInterface>
        </joint>
        <actuator name="right_ur_arm_shoulder_pan_joint_motor">
            <hardwareInterface>hardware_interface/EffortJointInterface</hardwareInterface>
            <mechanicalReduction>1</mechanicalReduction>
        </actuator>
    </transmission>
    <transmission name="trans_right_ur_arm_shoulder_lift_joint">
        <type>transmission_interface/SimpleTransmission</type>
        <joint name="right_ur_arm_shoulder_lift_joint">
            <hardwareInterface>hardware_interface/EffortJointInterface</hardwareInterface>
        </joint>
        <actuator name="right_ur_arm_shoulder_lift_joint_motor">
            <hardwareInterface>hardware_interface/EffortJointInterface</hardwareInterface>
            <mechanicalReduction>1</mechanicalReduction>
        </actuator>
    </transmission>
    <transmission name="trans_right_ur_arm_elbow_joint">
        <type>transmission_interface/SimpleTransmission</type>
        <joint name="right_ur_arm_elbow_joint">
            <hardwareInterface>hardware_interface/EffortJointInterface</hardwareInterface>
        </joint>
        <actuator name="right_ur_arm_elbow_joint_motor">
            <hardwareInterface>hardware_interface/EffortJointInterface</hardwareInterface>
            <mechanicalReduction>1</mechanicalReduction>
        </actuator>
    </transmission>
    <transmission name="trans_right_ur_arm_wrist_1_joint">
        <type>transmission_interface/SimpleTransmission</type>
        <joint name="right_ur_arm_wrist_1_joint">
            <hardwareInterface>hardware_interface/EffortJointInterface</hardwareInterface>
        </joint>
        <actuator name="right_ur_arm_wrist_1_joint_motor">
            <hardwareInterface>hardware_interface/EffortJointInterface</hardwareInterface>
            <mechanicalReduction>1</mechanicalReduction>
        </actuator>
    </transmission>
    <transmission name="trans_right_ur_arm_wrist_2_joint">
        <type>transmission_interface/SimpleTransmission</type>
        <joint name="right_ur_arm_wrist_2_joint">
            <hardwareInterface>hardware_interface/EffortJointInterface</hardwareInterface>
        </joint>
        <actuator name="right_ur_arm_wrist_2_joint_motor">
            <hardwareInterface>hardware_interface/EffortJointInterface</hardwareInterface>
            <mechanicalReduction>1</mechanicalReduction>
        </actuator>
    </transmission>
    <transmission name="trans_right_ur_arm_wrist_3_joint">
        <type>transmission_interface/SimpleTransmission</type>
        <joint name="right_ur_arm_wrist_3_joint">
            <hardwareInterface>hardware_interface/EffortJointInterface</hardwareInterface>
        </joint>
        <actuator name="right_ur_arm_wrist_3_joint_motor">
            <hardwareInterface>hardware_interface/EffortJointInterface</hardwareInterface>
            <mechanicalReduction>1</mechanicalReduction>
        </actuator>
    </transmission>
    <transmission name="trans_left_ur_arm_shoulder_pan_joint">
        <type>transmission_interface/SimpleTransmission</type>
        <joint name="left_ur_arm_shoulder_pan_joint">
            <hardwareInterface>hardware_interface/EffortJointInterface</hardwareInterface>
        </joint>
        <actuator name="left_ur_arm_shoulder_pan_joint_motor">
            <hardwareInterface>hardware_interface/EffortJointInterface</hardwareInterface>
            <mechanicalReduction>1</mechanicalReduction>
        </actuator>
    </transmission>
    <transmission name="trans_left_ur_arm_shoulder_lift_joint">
        <type>transmission_interface/SimpleTransmission</type>
        <joint name="left_ur_arm_shoulder_lift_joint">
            <hardwareInterface>hardware_interface/EffortJointInterface</hardwareInterface>
        </joint>
        <actuator name="left_ur_arm_shoulder_lift_joint_motor">
            <hardwareInterface>hardware_interface/EffortJointInterface</hardwareInterface>
            <mechanicalReduction>1</mechanicalReduction>
        </actuator>
    </transmission>
    <transmission name="trans_left_ur_arm_elbow_joint">
        <type>transmission_interface/SimpleTransmission</type>
        <joint name="left_ur_arm_elbow_joint">
            <hardwareInterface>hardware_interface/EffortJointInterface</hardwareInterface>
        </joint>
        <actuator name="left_ur_arm_elbow_joint_motor">
            <hardwareInterface>hardware_interface/EffortJointInterface</hardwareInterface>
            <mechanicalReduction>1</mechanicalReduction>
        </actuator>
    </transmission>
    <transmission name="trans_left_ur_arm_wrist_1_joint">
        <type>transmission_interface/SimpleTransmission</type>
        <joint name="left_ur_arm_wrist_1_joint">
            <hardwareInterface>hardware_interface/EffortJointInterface</hardwareInterface>
        </joint>
        <actuator name="left_ur_arm_wrist_1_joint_motor">
            <hardwareInterface>hardware_interface/EffortJointInterface</hardwareInterface>
            <mechanicalReduction>1</mechanicalReduction>
        </actuator>
    </transmission>
    <transmission name="trans_left_ur_arm_wrist_2_joint">
        <type>transmission_interface/SimpleTransmission</type>
        <joint name="left_ur_arm_wrist_2_joint">
            <hardwareInterface>hardware_interface/EffortJointInterface</hardwareInterface>
        </joint>
        <actuator name="left_ur_arm_wrist_2_joint_motor">
            <hardwareInterface>hardware_interface/EffortJointInterface</hardwareInterface>
            <mechanicalReduction>1</mechanicalReduction>
        </actuator>
    </transmission>
    <transmission name="trans_left_ur_arm_wrist_3_joint">
        <type>transmission_interface/SimpleTransmission</type>
        <joint name="left_ur_arm_wrist_3_joint">
            <hardwareInterface>hardware_interface/EffortJointInterface</hardwareInterface>
        </joint>
        <actuator name="left_ur_arm_wrist_3_joint_motor">
            <hardwareInterface>hardware_interface/EffortJointInterface</hardwareInterface>
            <mechanicalReduction>1</mechanicalReduction>
        </actuator>
    </transmission>
    <gazebo>
        <plugin name="gazebo_ros_control" filename="libgazebo_ros_control.so">
            <robotNamespace>/</robotNamespace>
        </plugin>
    </gazebo>

</robot>
